<?xml version="1.0"?>
<sdf version='1.5'>
  <model name='ductedfan2'>
    <pose>0 0 0.5 0 0 0</pose>
    <link name='base_link'>
      <pose>0 0 0 0 0 0</pose>
      <inertial>
          <mass>1.51082</mass>
          <inertia>
            <ixx>0.0276508</ixx>
            <ixy>0</ixy>
            <ixz>0.00026669</ixz>
            <iyy>0.0275263</iyy>
            <iyz>0.00028741</iyz>
            <izz>0.00619679</izz>
          </inertia>
          <pose>-4.1e-05 -7.6e-05 0.042069 0 -0 0</pose>
      </inertial>
      <collision name='base_link_collision'>
        <geometry>
          <!--mesh>
            <uri>model://ductedfan2/meshes/DF - Product-gazebo-1.STL</uri>
          </mesh-->
          <box>
            <size>0.25 0.25 0.52</size>
          </box>
        </geometry>
        <!--surface>
          <contact>
            <ode>
              <max_vel>10</max_vel>
              <min_depth>0.01</min_depth>
            </ode>
          </contact>
          <friction>
            <ode>
              <mu>1.0</mu>
            </ode>
          </friction>
        </surface-->
      </collision>
      <visual name='base_link_visual'>
        <pose>0.0 0 -0.0 0 0 0</pose>
        <geometry>
          <mesh>
            <scale>1 1 1</scale>
            <uri>model://ductedfan2/meshes/DF - Product-gazebo-1.STL</uri>
          </mesh>
        </geometry>
        <material>
          <script>
            <name>Gazebo/DarkGrey</name>
            <uri>__default__</uri>
          </script>
        </material>
      </visual>
      <gravity>1</gravity>
      <velocity_decay/>
      <self_collide>0</self_collide>
    </link>
    <link name='ductedfan2/imu_link'>
      <pose>0 0 0 0 0 0</pose>
      <inertial>
        <pose>0 0 0 0 0 0</pose>
        <mass>0.015</mass>
        <inertia>
          <ixx>1e-05</ixx>
          <ixy>0</ixy>
          <ixz>0</ixz>
          <iyy>1e-05</iyy>
          <iyz>0</iyz>
          <izz>1e-05</izz>
        </inertia>
      </inertial>
    </link>
    <joint name='ductedfan2/imu_joint' type='revolute'>
      <child>ductedfan2/imu_link</child>
      <parent>base_link</parent>
      <axis>
        <xyz>1 0 0</xyz>
        <limit>
          <lower>0</lower>
          <upper>0</upper>
          <effort>0</effort>
          <velocity>0</velocity>
        </limit>
        <dynamics>
          <spring_reference>0</spring_reference>
          <spring_stiffness>0</spring_stiffness>
        </dynamics>
        <use_parent_model_frame>1</use_parent_model_frame>
      </axis>
    </joint>
    <!--link name='ductedfan2/airspeed_link'>
      <pose>0 0 0 0 0 0</pose>
      <inertial>
        <pose>0 0 0 0 0 0</pose>
        <mass>0.015</mass>
        <inertia>
          <ixx>1e-05</ixx>
          <ixy>0</ixy>
          <ixz>0</ixz>
          <iyy>1e-05</iyy>
          <iyz>0</iyz>
          <izz>1e-05</izz>
        </inertia>
      </inertial>
    </link>
    <joint name='ductedfan2/airspeed_joint' type='revolute'>
      <child>ductedfan2/airspeed_link</child>
      <parent>base_link</parent>
      <axis>
        <xyz>1 0 0</xyz>
        <limit>
          <lower>0</lower>
          <upper>0</upper>
          <effort>0</effort>
          <velocity>0</velocity>
        </limit>
        <dynamics>
          <spring_reference>0</spring_reference>
          <spring_stiffness>0</spring_stiffness>
        </dynamics>
        <use_parent_model_frame>1</use_parent_model_frame>
      </axis>
    </joint-->
    <link name='cspitch'>
      <inertial>
        <mass>0.149682</mass>
        <inertia>
          <ixx>0.00066011</ixx>
          <ixy>0</ixy>
          <ixz>0</ixz>
          <iyy>8.5e-05</iyy>
          <iyz>0</iyz>
          <izz>0.000689</izz>
        </inertia>
        <pose>0.000401 0 -0.210756 0 -0 0</pose>
      </inertial>
      <!--inertial>
        <mass>0.0000001</mass>
        <inertia>
          <ixx>0.0000001</ixx>
          <ixy>0</ixy>
          <ixz>0</ixz>
          <iyy>0.0000001</iyy>
          <iyz>0</iyz>
          <izz>0.0000001</izz>
        </inertia>
        <pose>0.0 0 -0.0 0 -0 0</pose>
      </inertial-->
      <pose>0 0 0 0 -0 0</pose>
      <gravity>1</gravity>
      <self_collide>0</self_collide>
      <kinematic>0</kinematic>
      <enable_wind>0</enable_wind>
      <visual name='visual'>
        <pose>0 0 0 0 -0 0</pose>
        <geometry>
          <mesh>
            <uri>model://ductedfan2/meshes/DF - control surface-60-2-1.STL</uri>
            <scale>1 1 1</scale>
          </mesh>
        </geometry>
        <material>
          <script>
            <name>Gazebo/Blue</name>
            <uri>__default__</uri>
          </script>
        </material>
        <transparency>0</transparency>
        <cast_shadows>1</cast_shadows>
      </visual>
    </link>
    <link name='csroll'>
      <inertial>
        <mass>0.138453</mass>
        <inertia>
          <ixx>9.877e-05</ixx>
          <ixy>0</ixy>
          <ixz>0</ixz>
          <iyy>0.00067119</iyy>
          <iyz>0</iyz>
          <izz>0.00068256</izz>
        </inertia>
        <pose>0 0.000824 -0.20992 0 -0 0</pose>
      </inertial>
      <!--inertial>
        <mass>0.0000001</mass>
        <inertia>
          <ixx>0.0000001</ixx>
          <ixy>0</ixy>
          <ixz>0</ixz>
          <iyy>0.0000001</iyy>
          <iyz>0</iyz>
          <izz>0.0000001</izz>
        </inertia>
        <pose>0 0.0 -0.0 0 -0 0</pose>
      </inertial-->
      <pose>0 0 0 0 -0 0</pose>
      <gravity>1</gravity>
      <self_collide>0</self_collide>
      <kinematic>0</kinematic>
      <enable_wind>0</enable_wind>
      <visual name='visual'>
        <pose>0 0 0 0 -0 0</pose>
        <geometry>
          <mesh>
            <uri>model://ductedfan2/meshes/DF - control surface-60-67-3.STL</uri>
            <scale>1 1 1</scale>
          </mesh>
        </geometry>
        <material>
          <script>
            <name>Gazebo/Blue</name>
            <uri>__default__</uri>
          </script>
        </material>
        <transparency>0</transparency>
        <cast_shadows>1</cast_shadows>
      </visual>
    </link>
    <link name='r1'>
      <inertial>
        <mass>0.015678</mass>
        <inertia>
          <ixx>1.851e-05</ixx>
          <ixy>0</ixy>
          <ixz>0</ixz>
          <iyy>1.855e-05</iyy>
          <iyz>0</iyz>
          <izz>3.648e-05</izz>
        </inertia>
        <pose>0.000403 0.000759 -0.071513 0 -0 0</pose>
      </inertial>
      <pose>0 0 0 0 -0 0</pose>
      <gravity>1</gravity>
      <self_collide>0</self_collide>
      <kinematic>0</kinematic>
      <enable_wind>0</enable_wind>
      <visual name='visual'>
        <pose>0 0 0 0 -0 0</pose>
        <geometry>
          <mesh>
            <uri>model://ductedfan2/meshes/DF - fan-1.STL</uri>
            <scale>1 1 1</scale>
          </mesh>
        </geometry>
        <material>
          <script>
            <name>Gazebo/Blue</name>
            <uri>__default__</uri>
          </script>
        </material>
        <transparency>0</transparency>
        <cast_shadows>1</cast_shadows>
      </visual>
    </link>
    <link name='r2'>
      <inertial>
        <mass>0.015678</mass>
        <inertia>
          <ixx>1.851e-05</ixx>
          <ixy>0</ixy>
          <ixz>0</ixz>
          <iyy>1.855e-05</iyy>
          <iyz>0</iyz>
          <izz>3.648e-05</izz>
        </inertia>
        <pose>0.000403 0.000759 -0.154513 0 -0 0</pose>
      </inertial>
      <pose>0 0 0 0 -0 0</pose>
      <gravity>1</gravity>
      <self_collide>0</self_collide>
      <kinematic>0</kinematic>
      <enable_wind>0</enable_wind>
      <visual name='visual'>
        <pose>0 0 0 0 -0 0</pose>
        <geometry>
          <mesh>
            <uri>model://ductedfan2/meshes/DF - fan-2.STL</uri>
            <scale>1 1 1</scale>
          </mesh>
        </geometry>
        <material>
          <script>
            <name>Gazebo/Blue</name>
            <uri>__default__</uri>
          </script>
        </material>
        <transparency>0</transparency>
        <cast_shadows>1</cast_shadows>
      </visual>
    </link>
    <joint name='cspitch_joint' type='revolute'>
      <parent>base_link</parent>
      <child>cspitch</child>
      <pose>0.00037 0 -0.19763 0 -0 0</pose>
      <axis>
        <xyz>0 1 0</xyz>
        <limit>
          <lower>-0.35</lower>
          <upper>0.35</upper>
        </limit>
        <dynamics>
          <damping>0.01</damping>
          <friction>0.0</friction>
          <spring_reference>0</spring_reference>
          <spring_stiffness>0</spring_stiffness>
        </dynamics>
      </axis>
    </joint>
    <joint name='csroll_joint' type='revolute'>
      <parent>base_link</parent>
      <child>csroll</child>
      <pose>0 0.00074 -0.19763 0 -0 0</pose>
      <axis>
        <xyz>1 0 0</xyz>
        <limit>
          <lower>-0.35</lower>
          <upper>0.35</upper>
        </limit>
        <dynamics>
          <damping>0.01</damping>
          <friction>0.0</friction>
          <spring_reference>0</spring_reference>
          <spring_stiffness>0</spring_stiffness>
        </dynamics>
      </axis>
    </joint>
    <joint name='r1_joint' type='revolute'>
      <parent>base_link</parent>
      <child>r1</child>
      <pose>0.000403 0.000759 -0.071513 0 -0 0</pose>
      <axis>
        <xyz>0 0 1</xyz>
        <limit>
          <lower>-1e+16</lower>
          <upper>1e+16</upper>
          <effort>-1</effort>
          <velocity>-1</velocity>
        </limit>
        <dynamics>
          <spring_reference>0</spring_reference>
          <spring_stiffness>0</spring_stiffness>
          <damping>0.0</damping>
          <friction>0</friction>
        </dynamics>
      </axis>
      <physics>
        <ode>
          <limit>
            <cfm>0</cfm>
            <erp>0.2</erp>
          </limit>
          <suspension>
            <cfm>0</cfm>
            <erp>0.2</erp>
          </suspension>
        </ode>
      </physics>
    </joint>
    <joint name='r2_joint' type='revolute'>
      <parent>base_link</parent>
      <child>r2</child>
      <pose>0.000403 0.000759 -0.154513 0 -0 0</pose>
      <axis>
        <xyz>0 0 1</xyz>
        <limit>
          <lower>-1e+16</lower>
          <upper>1e+16</upper>
          <effort>-1</effort>
          <velocity>-1</velocity>
        </limit>
        <dynamics>
          <spring_reference>0</spring_reference>
          <spring_stiffness>0</spring_stiffness>
          <damping>0.0</damping>
          <friction>0</friction>
        </dynamics>
      </axis>
      <physics>
        <ode>
          <limit>
            <cfm>0</cfm>
            <erp>0.2</erp>
          </limit>
          <suspension>
            <cfm>0</cfm>
            <erp>0.2</erp>
          </suspension>
        </ode>
      </physics>
    </joint>
    <include>
      <uri>model://gps</uri>
      <pose>0 0 0 0 0 0</pose>
      <name>gps</name>
    </include>
    <joint name='gps_joint' type='fixed'>
      <child>gps::link</child>
      <parent>base_link</parent>
    </joint>
    <plugin name="csroll_plugin" filename="libLiftDragPlugin.so">
      <is_ductedfan>1</is_ductedfan>
      <num_of_propeller>2</num_of_propeller>
      <wind_from_propeller>
        <propeller name="up_propeller">
          <propeller_index>0</propeller_index>
          <propeller_joint>r1_joint</propeller_joint>
          <propeller_wind_constant>0.18</propeller_wind_constant>
        </propeller>
        <propeller name="down_propeller">
          <propeller_index>1</propeller_index>
          <propeller_joint>r2_joint</propeller_joint>
          <propeller_wind_constant>0.18</propeller_wind_constant>
        </propeller>
      </wind_from_propeller>
      <a0>0</a0>
      <cla>0</cla>
      <cda>0</cda>
      <cma>0</cma>
      <alpha_stall>0.6</alpha_stall>
      <cla_stall>0</cla_stall>
      <cda_stall>0.0</cda_stall>
      <cma_stall>0</cma_stall>
      <cp>0 0 -0.20763</cp>
      <area>0.0018</area>
      <air_density>1.2041</air_density>
      <forward>0 0 1</forward>
      <upward>0 -1 0</upward>
      <link_name>base_link</link_name>
      <control_joint_name>csroll_joint</control_joint_name>
      <control_joint_rad_to_cl>8</control_joint_rad_to_cl>
      <robotNamespace></robotNamespace>
      <windSubTopic>world_wind</windSubTopic>
    </plugin>
    <plugin name="cspitch_plugin" filename="libLiftDragPlugin.so">
      <is_ductedfan>1</is_ductedfan>
      <num_of_propeller>2</num_of_propeller>
      <wind_from_propeller>
        <propeller name="up_propeller">
          <propeller_index>0</propeller_index>
          <propeller_joint>r1_joint</propeller_joint>
          <propeller_wind_constant>0.18</propeller_wind_constant>
        </propeller>
        <propeller name="down_propeller">
          <propeller_index>1</propeller_index>
          <propeller_joint>r2_joint</propeller_joint>
          <propeller_wind_constant>0.18</propeller_wind_constant>
        </propeller>
      </wind_from_propeller>
      <a0>0</a0>
      <cla>0</cla>
      <cda>0</cda>
      <cma>0</cma>
      <alpha_stall>0.6</alpha_stall>
      <cla_stall>0</cla_stall>
      <cda_stall>0.0</cda_stall>
      <cma_stall>0</cma_stall>
      <cp>0 0 -0.20763</cp>
      <area>0.0018</area>
      <air_density>1.2041</air_density>
      <forward>0 0 1</forward>
      <upward>1 0 0</upward>
      <link_name>base_link</link_name>
      <control_joint_name>cspitch_joint</control_joint_name>
      <control_joint_rad_to_cl>8</control_joint_rad_to_cl>
      <robotNamespace></robotNamespace>
      <windSubTopic>world_wind</windSubTopic>
    </plugin>
    <plugin name='r1_plugin' filename='libgazebo_motor_model.so'>
      <robotNamespace></robotNamespace>
      <jointName>r1_joint</jointName>
      <linkName>r1</linkName>
      <turningDirection>cw</turningDirection>
      <timeConstantUp>0.0125</timeConstantUp>
      <timeConstantDown>0.025</timeConstantDown>
      <maxRotVelocity>2000</maxRotVelocity>
      <motorConstant>8.54858e-06</motorConstant>
      <momentConstant>0.01</momentConstant>
      <commandSubTopic>/gazebo/command/motor_speed</commandSubTopic>
      <motorNumber>0</motorNumber>
      <rotorDragCoefficient>8.06428e-05</rotorDragCoefficient>
      <rollingMomentCoefficient>1e-06</rollingMomentCoefficient>
      <motorSpeedPubTopic>/motor_speed/0</motorSpeedPubTopic>
      <rotorVelocitySlowdownSim>10</rotorVelocitySlowdownSim>
      <robotNamespace></robotNamespace>
    </plugin>
    <plugin name='r2_plugin' filename='libgazebo_motor_model.so'>
      <robotNamespace></robotNamespace>
      <jointName>r2_joint</jointName>
      <linkName>r2</linkName>
      <turningDirection>ccw</turningDirection>
      <timeConstantUp>0.0125</timeConstantUp>
      <timeConstantDown>0.025</timeConstantDown>
      <maxRotVelocity>2000</maxRotVelocity>
      <motorConstant>8.54858e-06</motorConstant>
      <momentConstant>0.01</momentConstant>
      <commandSubTopic>/gazebo/command/motor_speed</commandSubTopic>
      <motorNumber>1</motorNumber>
      <rotorDragCoefficient>8.06428e-05</rotorDragCoefficient>
      <rollingMomentCoefficient>1e-06</rollingMomentCoefficient>
      <motorSpeedPubTopic>/motor_speed/1</motorSpeedPubTopic>
      <rotorVelocitySlowdownSim>10</rotorVelocitySlowdownSim>
    </plugin>
    <plugin name='gazebo_imu_plugin' filename='libgazebo_imu_plugin.so'>
      <robotNamespace></robotNamespace>
      <linkName>ductedfan2/imu_link</linkName>
      <imuTopic>/imu</imuTopic>
      <gyroscopeNoiseDensity>0.00018665</gyroscopeNoiseDensity>
      <gyroscopeRandomWalk>3.8785e-05</gyroscopeRandomWalk>
      <gyroscopeBiasCorrelationTime>1000.0</gyroscopeBiasCorrelationTime>
      <gyroscopeTurnOnBiasSigma>0.0087</gyroscopeTurnOnBiasSigma>
      <accelerometerNoiseDensity>0.00186</accelerometerNoiseDensity>
      <accelerometerRandomWalk>0.006</accelerometerRandomWalk>
      <accelerometerBiasCorrelationTime>300.0</accelerometerBiasCorrelationTime>
      <accelerometerTurnOnBiasSigma>0.196</accelerometerTurnOnBiasSigma>
    </plugin>
    <plugin name='groundtruth_plugin' filename='libgazebo_groundtruth_plugin.so'>
      <robotNamespace/>
    </plugin>
    <plugin name='magnetometer_plugin' filename='libgazebo_magnetometer_plugin.so'>
      <robotNamespace/>
      <pubRate>100</pubRate>
      <noiseDensity>0.0004</noiseDensity>
      <randomWalk>6.4e-06</randomWalk>
      <biasCorrelationTime>600</biasCorrelationTime>
      <magTopic>/mag</magTopic>
    </plugin>
    <plugin name='barometer_plugin' filename='libgazebo_barometer_plugin.so'>
      <robotNamespace/>
      <pubRate>50</pubRate>
      <baroTopic>/baro</baroTopic>
    </plugin>
    <!--plugin name='airspeed_plugin' filename='libgazebo_airspeed_plugin.so'>
      <robotNamespace/>
      <linkName>ductedfan2/airspeed_link</linkName>
    </plugin-->
    <plugin name='mavlink_interface' filename='libgazebo_mavlink_interface.so'>
      <robotNamespace></robotNamespace>
      <imuSubTopic>/imu</imuSubTopic>
      <magSubTopic>/mag</magSubTopic>
      <baroSubTopic>/baro</baroSubTopic>
      <mavlink_addr>INADDR_ANY</mavlink_addr>
      <mavlink_tcp_port>{{ mavlink_tcp_port }}</mavlink_tcp_port>
      <mavlink_udp_port>{{ mavlink_udp_port }}</mavlink_udp_port>
      <serialEnabled>{{ serial_enabled }}</serialEnabled>
      <serialDevice>{{ serial_device }}</serialDevice>
      <baudRate>{{ serial_baudrate }}</baudRate>
      <qgc_addr>INADDR_ANY</qgc_addr>
      <qgc_udp_port>14550</qgc_udp_port>
      <sdk_addr>INADDR_ANY</sdk_addr>
      <sdk_udp_port>14540</sdk_udp_port>
      <hil_mode>{{ hil_mode }}</hil_mode>
      <hil_state_level>false</hil_state_level>
      <enable_lockstep>true</enable_lockstep>
      <use_tcp>true</use_tcp>
      <motorSpeedCommandPubTopic>/gazebo/command/motor_speed</motorSpeedCommandPubTopic>
      <control_channels>
        <channel name="up_rotor">
          <input_index>0</input_index>
          <input_offset>0</input_offset>
          <input_scaling>1500</input_scaling>
          <zero_position_disarmed>0</zero_position_disarmed>
          <zero_position_armed>0</zero_position_armed>
          <joint_control_type>velocity</joint_control_type>
          <joint_name>r1_joint</joint_name>
        </channel>
        <channel name="down_rotor">
          <input_index>1</input_index>
          <input_offset>0</input_offset>
          <input_scaling>1500</input_scaling>
          <zero_position_disarmed>0</zero_position_disarmed>
          <zero_position_armed>0</zero_position_armed>
          <joint_control_type>velocity</joint_control_type>
          <joint_name>r2_joint</joint_name>
        </channel>
        <channel name="roll">
          <input_index>2</input_index>
          <input_offset>0</input_offset>
          <input_scaling>0.35</input_scaling>
          <zero_position_disarmed>0</zero_position_disarmed>
          <zero_position_armed>0</zero_position_armed>
          <joint_control_type>position</joint_control_type>
          <joint_name>csroll_joint</joint_name>
          <joint_control_pid>
            <p>1</p>
            <i>0</i>
            <d>0</d>
            <iMax>0</iMax>
            <iMin>0</iMin>
            <cmdMax>20</cmdMax>
            <cmdMin>-20</cmdMin>
          </joint_control_pid>
        </channel>
        <channel name="pitch">
          <input_index>3</input_index>
          <input_offset>0</input_offset>
          <input_scaling>0.35</input_scaling>
          <zero_position_disarmed>0</zero_position_disarmed>
          <zero_position_armed>0</zero_position_armed>
          <joint_control_type>position</joint_control_type>
          <joint_name>cspitch_joint</joint_name>
          <joint_control_pid>
            <p>1</p>
            <i>0.0</i>
            <d>0</d>
            <iMax>0.5</iMax>
            <iMin>-0.5</iMin>
            <cmdMax>10</cmdMax>
            <cmdMin>-10</cmdMin>
            <errMax>20</errMax>
          </joint_control_pid>
        </channel>
      </control_channels>
    </plugin>
    <static>0</static>
  </model>
</sdf>
